Corriendo el sub-muestreo de genomas
Corri en la maquina: node-12.local
Corri el: Thu Feb 20 11:17:01 -05 2020
Exception ignored in: <generator object as_handle at 0x7f6b12d57258>
Traceback (most recent call last):
  File "/hpcfs/home/da.martinez33/anaconda3/lib/python3.6/site-packages/Bio/File.py", line 119, in as_handle
MemoryError: 
Exception ignored in: <generator object parse at 0x7f6b12dec1a8>
Traceback (most recent call last):
  File "/hpcfs/home/da.martinez33/anaconda3/lib/python3.6/site-packages/Bio/SeqIO/__init__.py", line 662, in parse
MemoryError: 
Inciando con (locusta)....

GCA_000516895.1_LocustGenomeV1_genomic.fna
MemoryError

During handling of the above exception, another exception occurred:

Traceback (most recent call last):
  File "locusta_sampling.py", line 106, in <module>
  File "locusta_sampling.py", line 32, in get_100_seq
  File "/hpcfs/home/da.martinez33/anaconda3/lib/python3.6/site-packages/Bio/SeqRecord.py", line 457, in __getitem__
MemoryError
